{
 "cells": [
  {
   "cell_type": "code",
   "execution_count": 12,
   "id": "9c4a16aa-5dfa-44e7-ac54-431bbcfc54eb",
   "metadata": {},
   "outputs": [
    {
     "name": "stderr",
     "output_type": "stream",
     "text": [
      "No model was supplied, defaulted to distilbert/distilbert-base-uncased-finetuned-sst-2-english and revision af0f99b (https://huggingface.co/distilbert/distilbert-base-uncased-finetuned-sst-2-english).\n",
      "Using a pipeline without specifying a model name and revision in production is not recommended.\n"
     ]
    },
    {
     "ename": "OSError",
     "evalue": "We couldn't connect to 'https://huggingface.co' to load this file, couldn't find it in the cached files and it looks like distilbert/distilbert-base-uncased-finetuned-sst-2-english is not the path to a directory containing a file named config.json.\nCheckout your internet connection or see how to run the library in offline mode at 'https://huggingface.co/docs/transformers/installation#offline-mode'.",
     "output_type": "error",
     "traceback": [
      "\u001b[1;31m---------------------------------------------------------------------------\u001b[0m",
      "\u001b[1;31mtimeout\u001b[0m                                   Traceback (most recent call last)",
      "File \u001b[1;32mD:\\Anaconda\\envs\\data_analysis\\lib\\site-packages\\urllib3\\connection.py:198\u001b[0m, in \u001b[0;36mHTTPConnection._new_conn\u001b[1;34m(self)\u001b[0m\n\u001b[0;32m    197\u001b[0m \u001b[38;5;28;01mtry\u001b[39;00m:\n\u001b[1;32m--> 198\u001b[0m     sock \u001b[38;5;241m=\u001b[39m \u001b[43mconnection\u001b[49m\u001b[38;5;241;43m.\u001b[39;49m\u001b[43mcreate_connection\u001b[49m\u001b[43m(\u001b[49m\n\u001b[0;32m    199\u001b[0m \u001b[43m        \u001b[49m\u001b[43m(\u001b[49m\u001b[38;5;28;43mself\u001b[39;49m\u001b[38;5;241;43m.\u001b[39;49m\u001b[43m_dns_host\u001b[49m\u001b[43m,\u001b[49m\u001b[43m \u001b[49m\u001b[38;5;28;43mself\u001b[39;49m\u001b[38;5;241;43m.\u001b[39;49m\u001b[43mport\u001b[49m\u001b[43m)\u001b[49m\u001b[43m,\u001b[49m\n\u001b[0;32m    200\u001b[0m \u001b[43m        \u001b[49m\u001b[38;5;28;43mself\u001b[39;49m\u001b[38;5;241;43m.\u001b[39;49m\u001b[43mtimeout\u001b[49m\u001b[43m,\u001b[49m\n\u001b[0;32m    201\u001b[0m \u001b[43m        \u001b[49m\u001b[43msource_address\u001b[49m\u001b[38;5;241;43m=\u001b[39;49m\u001b[38;5;28;43mself\u001b[39;49m\u001b[38;5;241;43m.\u001b[39;49m\u001b[43msource_address\u001b[49m\u001b[43m,\u001b[49m\n\u001b[0;32m    202\u001b[0m \u001b[43m        \u001b[49m\u001b[43msocket_options\u001b[49m\u001b[38;5;241;43m=\u001b[39;49m\u001b[38;5;28;43mself\u001b[39;49m\u001b[38;5;241;43m.\u001b[39;49m\u001b[43msocket_options\u001b[49m\u001b[43m,\u001b[49m\n\u001b[0;32m    203\u001b[0m \u001b[43m    \u001b[49m\u001b[43m)\u001b[49m\n\u001b[0;32m    204\u001b[0m \u001b[38;5;28;01mexcept\u001b[39;00m socket\u001b[38;5;241m.\u001b[39mgaierror \u001b[38;5;28;01mas\u001b[39;00m e:\n",
      "File \u001b[1;32mD:\\Anaconda\\envs\\data_analysis\\lib\\site-packages\\urllib3\\util\\connection.py:85\u001b[0m, in \u001b[0;36mcreate_connection\u001b[1;34m(address, timeout, source_address, socket_options)\u001b[0m\n\u001b[0;32m     84\u001b[0m \u001b[38;5;28;01mtry\u001b[39;00m:\n\u001b[1;32m---> 85\u001b[0m     \u001b[38;5;28;01mraise\u001b[39;00m err\n\u001b[0;32m     86\u001b[0m \u001b[38;5;28;01mfinally\u001b[39;00m:\n\u001b[0;32m     87\u001b[0m     \u001b[38;5;66;03m# Break explicitly a reference cycle\u001b[39;00m\n",
      "File \u001b[1;32mD:\\Anaconda\\envs\\data_analysis\\lib\\site-packages\\urllib3\\util\\connection.py:73\u001b[0m, in \u001b[0;36mcreate_connection\u001b[1;34m(address, timeout, source_address, socket_options)\u001b[0m\n\u001b[0;32m     72\u001b[0m     sock\u001b[38;5;241m.\u001b[39mbind(source_address)\n\u001b[1;32m---> 73\u001b[0m \u001b[43msock\u001b[49m\u001b[38;5;241;43m.\u001b[39;49m\u001b[43mconnect\u001b[49m\u001b[43m(\u001b[49m\u001b[43msa\u001b[49m\u001b[43m)\u001b[49m\n\u001b[0;32m     74\u001b[0m \u001b[38;5;66;03m# Break explicitly a reference cycle\u001b[39;00m\n",
      "\u001b[1;31mtimeout\u001b[0m: timed out",
      "\nThe above exception was the direct cause of the following exception:\n",
      "\u001b[1;31mConnectTimeoutError\u001b[0m                       Traceback (most recent call last)",
      "File \u001b[1;32mD:\\Anaconda\\envs\\data_analysis\\lib\\site-packages\\urllib3\\connectionpool.py:793\u001b[0m, in \u001b[0;36mHTTPConnectionPool.urlopen\u001b[1;34m(self, method, url, body, headers, retries, redirect, assert_same_host, timeout, pool_timeout, release_conn, chunked, body_pos, preload_content, decode_content, **response_kw)\u001b[0m\n\u001b[0;32m    792\u001b[0m \u001b[38;5;66;03m# Make the request on the HTTPConnection object\u001b[39;00m\n\u001b[1;32m--> 793\u001b[0m response \u001b[38;5;241m=\u001b[39m \u001b[38;5;28mself\u001b[39m\u001b[38;5;241m.\u001b[39m_make_request(\n\u001b[0;32m    794\u001b[0m     conn,\n\u001b[0;32m    795\u001b[0m     method,\n\u001b[0;32m    796\u001b[0m     url,\n\u001b[0;32m    797\u001b[0m     timeout\u001b[38;5;241m=\u001b[39mtimeout_obj,\n\u001b[0;32m    798\u001b[0m     body\u001b[38;5;241m=\u001b[39mbody,\n\u001b[0;32m    799\u001b[0m     headers\u001b[38;5;241m=\u001b[39mheaders,\n\u001b[0;32m    800\u001b[0m     chunked\u001b[38;5;241m=\u001b[39mchunked,\n\u001b[0;32m    801\u001b[0m     retries\u001b[38;5;241m=\u001b[39mretries,\n\u001b[0;32m    802\u001b[0m     response_conn\u001b[38;5;241m=\u001b[39mresponse_conn,\n\u001b[0;32m    803\u001b[0m     preload_content\u001b[38;5;241m=\u001b[39mpreload_content,\n\u001b[0;32m    804\u001b[0m     decode_content\u001b[38;5;241m=\u001b[39mdecode_content,\n\u001b[0;32m    805\u001b[0m     \u001b[38;5;241m*\u001b[39m\u001b[38;5;241m*\u001b[39mresponse_kw,\n\u001b[0;32m    806\u001b[0m )\n\u001b[0;32m    808\u001b[0m \u001b[38;5;66;03m# Everything went great!\u001b[39;00m\n",
      "File \u001b[1;32mD:\\Anaconda\\envs\\data_analysis\\lib\\site-packages\\urllib3\\connectionpool.py:491\u001b[0m, in \u001b[0;36mHTTPConnectionPool._make_request\u001b[1;34m(self, conn, method, url, body, headers, retries, timeout, chunked, response_conn, preload_content, decode_content, enforce_content_length)\u001b[0m\n\u001b[0;32m    490\u001b[0m         new_e \u001b[38;5;241m=\u001b[39m _wrap_proxy_error(new_e, conn\u001b[38;5;241m.\u001b[39mproxy\u001b[38;5;241m.\u001b[39mscheme)\n\u001b[1;32m--> 491\u001b[0m     \u001b[38;5;28;01mraise\u001b[39;00m new_e\n\u001b[0;32m    493\u001b[0m \u001b[38;5;66;03m# conn.request() calls http.client.*.request, not the method in\u001b[39;00m\n\u001b[0;32m    494\u001b[0m \u001b[38;5;66;03m# urllib3.request. It also calls makefile (recv) on the socket.\u001b[39;00m\n",
      "File \u001b[1;32mD:\\Anaconda\\envs\\data_analysis\\lib\\site-packages\\urllib3\\connectionpool.py:467\u001b[0m, in \u001b[0;36mHTTPConnectionPool._make_request\u001b[1;34m(self, conn, method, url, body, headers, retries, timeout, chunked, response_conn, preload_content, decode_content, enforce_content_length)\u001b[0m\n\u001b[0;32m    466\u001b[0m \u001b[38;5;28;01mtry\u001b[39;00m:\n\u001b[1;32m--> 467\u001b[0m     \u001b[38;5;28;43mself\u001b[39;49m\u001b[38;5;241;43m.\u001b[39;49m\u001b[43m_validate_conn\u001b[49m\u001b[43m(\u001b[49m\u001b[43mconn\u001b[49m\u001b[43m)\u001b[49m\n\u001b[0;32m    468\u001b[0m \u001b[38;5;28;01mexcept\u001b[39;00m (SocketTimeout, BaseSSLError) \u001b[38;5;28;01mas\u001b[39;00m e:\n",
      "File \u001b[1;32mD:\\Anaconda\\envs\\data_analysis\\lib\\site-packages\\urllib3\\connectionpool.py:1099\u001b[0m, in \u001b[0;36mHTTPSConnectionPool._validate_conn\u001b[1;34m(self, conn)\u001b[0m\n\u001b[0;32m   1098\u001b[0m \u001b[38;5;28;01mif\u001b[39;00m conn\u001b[38;5;241m.\u001b[39mis_closed:\n\u001b[1;32m-> 1099\u001b[0m     \u001b[43mconn\u001b[49m\u001b[38;5;241;43m.\u001b[39;49m\u001b[43mconnect\u001b[49m\u001b[43m(\u001b[49m\u001b[43m)\u001b[49m\n\u001b[0;32m   1101\u001b[0m \u001b[38;5;66;03m# TODO revise this, see https://github.com/urllib3/urllib3/issues/2791\u001b[39;00m\n",
      "File \u001b[1;32mD:\\Anaconda\\envs\\data_analysis\\lib\\site-packages\\urllib3\\connection.py:616\u001b[0m, in \u001b[0;36mHTTPSConnection.connect\u001b[1;34m(self)\u001b[0m\n\u001b[0;32m    615\u001b[0m sock: socket\u001b[38;5;241m.\u001b[39msocket \u001b[38;5;241m|\u001b[39m ssl\u001b[38;5;241m.\u001b[39mSSLSocket\n\u001b[1;32m--> 616\u001b[0m \u001b[38;5;28mself\u001b[39m\u001b[38;5;241m.\u001b[39msock \u001b[38;5;241m=\u001b[39m sock \u001b[38;5;241m=\u001b[39m \u001b[38;5;28;43mself\u001b[39;49m\u001b[38;5;241;43m.\u001b[39;49m\u001b[43m_new_conn\u001b[49m\u001b[43m(\u001b[49m\u001b[43m)\u001b[49m\n\u001b[0;32m    617\u001b[0m server_hostname: \u001b[38;5;28mstr\u001b[39m \u001b[38;5;241m=\u001b[39m \u001b[38;5;28mself\u001b[39m\u001b[38;5;241m.\u001b[39mhost\n",
      "File \u001b[1;32mD:\\Anaconda\\envs\\data_analysis\\lib\\site-packages\\urllib3\\connection.py:207\u001b[0m, in \u001b[0;36mHTTPConnection._new_conn\u001b[1;34m(self)\u001b[0m\n\u001b[0;32m    206\u001b[0m \u001b[38;5;28;01mexcept\u001b[39;00m SocketTimeout \u001b[38;5;28;01mas\u001b[39;00m e:\n\u001b[1;32m--> 207\u001b[0m     \u001b[38;5;28;01mraise\u001b[39;00m ConnectTimeoutError(\n\u001b[0;32m    208\u001b[0m         \u001b[38;5;28mself\u001b[39m,\n\u001b[0;32m    209\u001b[0m         \u001b[38;5;124mf\u001b[39m\u001b[38;5;124m\"\u001b[39m\u001b[38;5;124mConnection to \u001b[39m\u001b[38;5;132;01m{\u001b[39;00m\u001b[38;5;28mself\u001b[39m\u001b[38;5;241m.\u001b[39mhost\u001b[38;5;132;01m}\u001b[39;00m\u001b[38;5;124m timed out. (connect timeout=\u001b[39m\u001b[38;5;132;01m{\u001b[39;00m\u001b[38;5;28mself\u001b[39m\u001b[38;5;241m.\u001b[39mtimeout\u001b[38;5;132;01m}\u001b[39;00m\u001b[38;5;124m)\u001b[39m\u001b[38;5;124m\"\u001b[39m,\n\u001b[0;32m    210\u001b[0m     ) \u001b[38;5;28;01mfrom\u001b[39;00m \u001b[38;5;21;01me\u001b[39;00m\n\u001b[0;32m    212\u001b[0m \u001b[38;5;28;01mexcept\u001b[39;00m \u001b[38;5;167;01mOSError\u001b[39;00m \u001b[38;5;28;01mas\u001b[39;00m e:\n",
      "\u001b[1;31mConnectTimeoutError\u001b[0m: (<urllib3.connection.HTTPSConnection object at 0x0000018F28FBF940>, 'Connection to huggingface.co timed out. (connect timeout=10)')",
      "\nThe above exception was the direct cause of the following exception:\n",
      "\u001b[1;31mMaxRetryError\u001b[0m                             Traceback (most recent call last)",
      "File \u001b[1;32mD:\\Anaconda\\envs\\data_analysis\\lib\\site-packages\\requests\\adapters.py:486\u001b[0m, in \u001b[0;36mHTTPAdapter.send\u001b[1;34m(self, request, stream, timeout, verify, cert, proxies)\u001b[0m\n\u001b[0;32m    485\u001b[0m \u001b[38;5;28;01mtry\u001b[39;00m:\n\u001b[1;32m--> 486\u001b[0m     resp \u001b[38;5;241m=\u001b[39m \u001b[43mconn\u001b[49m\u001b[38;5;241;43m.\u001b[39;49m\u001b[43murlopen\u001b[49m\u001b[43m(\u001b[49m\n\u001b[0;32m    487\u001b[0m \u001b[43m        \u001b[49m\u001b[43mmethod\u001b[49m\u001b[38;5;241;43m=\u001b[39;49m\u001b[43mrequest\u001b[49m\u001b[38;5;241;43m.\u001b[39;49m\u001b[43mmethod\u001b[49m\u001b[43m,\u001b[49m\n\u001b[0;32m    488\u001b[0m \u001b[43m        \u001b[49m\u001b[43murl\u001b[49m\u001b[38;5;241;43m=\u001b[39;49m\u001b[43murl\u001b[49m\u001b[43m,\u001b[49m\n\u001b[0;32m    489\u001b[0m \u001b[43m        \u001b[49m\u001b[43mbody\u001b[49m\u001b[38;5;241;43m=\u001b[39;49m\u001b[43mrequest\u001b[49m\u001b[38;5;241;43m.\u001b[39;49m\u001b[43mbody\u001b[49m\u001b[43m,\u001b[49m\n\u001b[0;32m    490\u001b[0m \u001b[43m        \u001b[49m\u001b[43mheaders\u001b[49m\u001b[38;5;241;43m=\u001b[39;49m\u001b[43mrequest\u001b[49m\u001b[38;5;241;43m.\u001b[39;49m\u001b[43mheaders\u001b[49m\u001b[43m,\u001b[49m\n\u001b[0;32m    491\u001b[0m \u001b[43m        \u001b[49m\u001b[43mredirect\u001b[49m\u001b[38;5;241;43m=\u001b[39;49m\u001b[38;5;28;43;01mFalse\u001b[39;49;00m\u001b[43m,\u001b[49m\n\u001b[0;32m    492\u001b[0m \u001b[43m        \u001b[49m\u001b[43massert_same_host\u001b[49m\u001b[38;5;241;43m=\u001b[39;49m\u001b[38;5;28;43;01mFalse\u001b[39;49;00m\u001b[43m,\u001b[49m\n\u001b[0;32m    493\u001b[0m \u001b[43m        \u001b[49m\u001b[43mpreload_content\u001b[49m\u001b[38;5;241;43m=\u001b[39;49m\u001b[38;5;28;43;01mFalse\u001b[39;49;00m\u001b[43m,\u001b[49m\n\u001b[0;32m    494\u001b[0m \u001b[43m        \u001b[49m\u001b[43mdecode_content\u001b[49m\u001b[38;5;241;43m=\u001b[39;49m\u001b[38;5;28;43;01mFalse\u001b[39;49;00m\u001b[43m,\u001b[49m\n\u001b[0;32m    495\u001b[0m \u001b[43m        \u001b[49m\u001b[43mretries\u001b[49m\u001b[38;5;241;43m=\u001b[39;49m\u001b[38;5;28;43mself\u001b[39;49m\u001b[38;5;241;43m.\u001b[39;49m\u001b[43mmax_retries\u001b[49m\u001b[43m,\u001b[49m\n\u001b[0;32m    496\u001b[0m \u001b[43m        \u001b[49m\u001b[43mtimeout\u001b[49m\u001b[38;5;241;43m=\u001b[39;49m\u001b[43mtimeout\u001b[49m\u001b[43m,\u001b[49m\n\u001b[0;32m    497\u001b[0m \u001b[43m        \u001b[49m\u001b[43mchunked\u001b[49m\u001b[38;5;241;43m=\u001b[39;49m\u001b[43mchunked\u001b[49m\u001b[43m,\u001b[49m\n\u001b[0;32m    498\u001b[0m \u001b[43m    \u001b[49m\u001b[43m)\u001b[49m\n\u001b[0;32m    500\u001b[0m \u001b[38;5;28;01mexcept\u001b[39;00m (ProtocolError, \u001b[38;5;167;01mOSError\u001b[39;00m) \u001b[38;5;28;01mas\u001b[39;00m err:\n",
      "File \u001b[1;32mD:\\Anaconda\\envs\\data_analysis\\lib\\site-packages\\urllib3\\connectionpool.py:847\u001b[0m, in \u001b[0;36mHTTPConnectionPool.urlopen\u001b[1;34m(self, method, url, body, headers, retries, redirect, assert_same_host, timeout, pool_timeout, release_conn, chunked, body_pos, preload_content, decode_content, **response_kw)\u001b[0m\n\u001b[0;32m    845\u001b[0m     new_e \u001b[38;5;241m=\u001b[39m ProtocolError(\u001b[38;5;124m\"\u001b[39m\u001b[38;5;124mConnection aborted.\u001b[39m\u001b[38;5;124m\"\u001b[39m, new_e)\n\u001b[1;32m--> 847\u001b[0m retries \u001b[38;5;241m=\u001b[39m \u001b[43mretries\u001b[49m\u001b[38;5;241;43m.\u001b[39;49m\u001b[43mincrement\u001b[49m\u001b[43m(\u001b[49m\n\u001b[0;32m    848\u001b[0m \u001b[43m    \u001b[49m\u001b[43mmethod\u001b[49m\u001b[43m,\u001b[49m\u001b[43m \u001b[49m\u001b[43murl\u001b[49m\u001b[43m,\u001b[49m\u001b[43m \u001b[49m\u001b[43merror\u001b[49m\u001b[38;5;241;43m=\u001b[39;49m\u001b[43mnew_e\u001b[49m\u001b[43m,\u001b[49m\u001b[43m \u001b[49m\u001b[43m_pool\u001b[49m\u001b[38;5;241;43m=\u001b[39;49m\u001b[38;5;28;43mself\u001b[39;49m\u001b[43m,\u001b[49m\u001b[43m \u001b[49m\u001b[43m_stacktrace\u001b[49m\u001b[38;5;241;43m=\u001b[39;49m\u001b[43msys\u001b[49m\u001b[38;5;241;43m.\u001b[39;49m\u001b[43mexc_info\u001b[49m\u001b[43m(\u001b[49m\u001b[43m)\u001b[49m\u001b[43m[\u001b[49m\u001b[38;5;241;43m2\u001b[39;49m\u001b[43m]\u001b[49m\n\u001b[0;32m    849\u001b[0m \u001b[43m\u001b[49m\u001b[43m)\u001b[49m\n\u001b[0;32m    850\u001b[0m retries\u001b[38;5;241m.\u001b[39msleep()\n",
      "File \u001b[1;32mD:\\Anaconda\\envs\\data_analysis\\lib\\site-packages\\urllib3\\util\\retry.py:515\u001b[0m, in \u001b[0;36mRetry.increment\u001b[1;34m(self, method, url, response, error, _pool, _stacktrace)\u001b[0m\n\u001b[0;32m    514\u001b[0m     reason \u001b[38;5;241m=\u001b[39m error \u001b[38;5;129;01mor\u001b[39;00m ResponseError(cause)\n\u001b[1;32m--> 515\u001b[0m     \u001b[38;5;28;01mraise\u001b[39;00m MaxRetryError(_pool, url, reason) \u001b[38;5;28;01mfrom\u001b[39;00m \u001b[38;5;21;01mreason\u001b[39;00m  \u001b[38;5;66;03m# type: ignore[arg-type]\u001b[39;00m\n\u001b[0;32m    517\u001b[0m log\u001b[38;5;241m.\u001b[39mdebug(\u001b[38;5;124m\"\u001b[39m\u001b[38;5;124mIncremented Retry for (url=\u001b[39m\u001b[38;5;124m'\u001b[39m\u001b[38;5;132;01m%s\u001b[39;00m\u001b[38;5;124m'\u001b[39m\u001b[38;5;124m): \u001b[39m\u001b[38;5;132;01m%r\u001b[39;00m\u001b[38;5;124m\"\u001b[39m, url, new_retry)\n",
      "\u001b[1;31mMaxRetryError\u001b[0m: HTTPSConnectionPool(host='huggingface.co', port=443): Max retries exceeded with url: /distilbert/distilbert-base-uncased-finetuned-sst-2-english/resolve/main/config.json (Caused by ConnectTimeoutError(<urllib3.connection.HTTPSConnection object at 0x0000018F28FBF940>, 'Connection to huggingface.co timed out. (connect timeout=10)'))",
      "\nDuring handling of the above exception, another exception occurred:\n",
      "\u001b[1;31mConnectTimeout\u001b[0m                            Traceback (most recent call last)",
      "File \u001b[1;32mD:\\Anaconda\\envs\\data_analysis\\lib\\site-packages\\huggingface_hub\\file_download.py:1722\u001b[0m, in \u001b[0;36m_get_metadata_or_catch_error\u001b[1;34m(repo_id, filename, repo_type, revision, endpoint, proxies, etag_timeout, headers, local_files_only, relative_filename, storage_folder)\u001b[0m\n\u001b[0;32m   1721\u001b[0m \u001b[38;5;28;01mtry\u001b[39;00m:\n\u001b[1;32m-> 1722\u001b[0m     metadata \u001b[38;5;241m=\u001b[39m \u001b[43mget_hf_file_metadata\u001b[49m\u001b[43m(\u001b[49m\u001b[43murl\u001b[49m\u001b[38;5;241;43m=\u001b[39;49m\u001b[43murl\u001b[49m\u001b[43m,\u001b[49m\u001b[43m \u001b[49m\u001b[43mproxies\u001b[49m\u001b[38;5;241;43m=\u001b[39;49m\u001b[43mproxies\u001b[49m\u001b[43m,\u001b[49m\u001b[43m \u001b[49m\u001b[43mtimeout\u001b[49m\u001b[38;5;241;43m=\u001b[39;49m\u001b[43metag_timeout\u001b[49m\u001b[43m,\u001b[49m\u001b[43m \u001b[49m\u001b[43mheaders\u001b[49m\u001b[38;5;241;43m=\u001b[39;49m\u001b[43mheaders\u001b[49m\u001b[43m)\u001b[49m\n\u001b[0;32m   1723\u001b[0m \u001b[38;5;28;01mexcept\u001b[39;00m EntryNotFoundError \u001b[38;5;28;01mas\u001b[39;00m http_error:\n",
      "File \u001b[1;32mD:\\Anaconda\\envs\\data_analysis\\lib\\site-packages\\huggingface_hub\\utils\\_validators.py:114\u001b[0m, in \u001b[0;36mvalidate_hf_hub_args.<locals>._inner_fn\u001b[1;34m(*args, **kwargs)\u001b[0m\n\u001b[0;32m    112\u001b[0m     kwargs \u001b[38;5;241m=\u001b[39m smoothly_deprecate_use_auth_token(fn_name\u001b[38;5;241m=\u001b[39mfn\u001b[38;5;241m.\u001b[39m\u001b[38;5;18m__name__\u001b[39m, has_token\u001b[38;5;241m=\u001b[39mhas_token, kwargs\u001b[38;5;241m=\u001b[39mkwargs)\n\u001b[1;32m--> 114\u001b[0m \u001b[38;5;28;01mreturn\u001b[39;00m fn(\u001b[38;5;241m*\u001b[39margs, \u001b[38;5;241m*\u001b[39m\u001b[38;5;241m*\u001b[39mkwargs)\n",
      "File \u001b[1;32mD:\\Anaconda\\envs\\data_analysis\\lib\\site-packages\\huggingface_hub\\file_download.py:1645\u001b[0m, in \u001b[0;36mget_hf_file_metadata\u001b[1;34m(url, token, proxies, timeout, library_name, library_version, user_agent, headers)\u001b[0m\n\u001b[0;32m   1644\u001b[0m \u001b[38;5;66;03m# Retrieve metadata\u001b[39;00m\n\u001b[1;32m-> 1645\u001b[0m r \u001b[38;5;241m=\u001b[39m \u001b[43m_request_wrapper\u001b[49m\u001b[43m(\u001b[49m\n\u001b[0;32m   1646\u001b[0m \u001b[43m    \u001b[49m\u001b[43mmethod\u001b[49m\u001b[38;5;241;43m=\u001b[39;49m\u001b[38;5;124;43m\"\u001b[39;49m\u001b[38;5;124;43mHEAD\u001b[39;49m\u001b[38;5;124;43m\"\u001b[39;49m\u001b[43m,\u001b[49m\n\u001b[0;32m   1647\u001b[0m \u001b[43m    \u001b[49m\u001b[43murl\u001b[49m\u001b[38;5;241;43m=\u001b[39;49m\u001b[43murl\u001b[49m\u001b[43m,\u001b[49m\n\u001b[0;32m   1648\u001b[0m \u001b[43m    \u001b[49m\u001b[43mheaders\u001b[49m\u001b[38;5;241;43m=\u001b[39;49m\u001b[43mheaders\u001b[49m\u001b[43m,\u001b[49m\n\u001b[0;32m   1649\u001b[0m \u001b[43m    \u001b[49m\u001b[43mallow_redirects\u001b[49m\u001b[38;5;241;43m=\u001b[39;49m\u001b[38;5;28;43;01mFalse\u001b[39;49;00m\u001b[43m,\u001b[49m\n\u001b[0;32m   1650\u001b[0m \u001b[43m    \u001b[49m\u001b[43mfollow_relative_redirects\u001b[49m\u001b[38;5;241;43m=\u001b[39;49m\u001b[38;5;28;43;01mTrue\u001b[39;49;00m\u001b[43m,\u001b[49m\n\u001b[0;32m   1651\u001b[0m \u001b[43m    \u001b[49m\u001b[43mproxies\u001b[49m\u001b[38;5;241;43m=\u001b[39;49m\u001b[43mproxies\u001b[49m\u001b[43m,\u001b[49m\n\u001b[0;32m   1652\u001b[0m \u001b[43m    \u001b[49m\u001b[43mtimeout\u001b[49m\u001b[38;5;241;43m=\u001b[39;49m\u001b[43mtimeout\u001b[49m\u001b[43m,\u001b[49m\n\u001b[0;32m   1653\u001b[0m \u001b[43m\u001b[49m\u001b[43m)\u001b[49m\n\u001b[0;32m   1654\u001b[0m hf_raise_for_status(r)\n",
      "File \u001b[1;32mD:\\Anaconda\\envs\\data_analysis\\lib\\site-packages\\huggingface_hub\\file_download.py:372\u001b[0m, in \u001b[0;36m_request_wrapper\u001b[1;34m(method, url, follow_relative_redirects, **params)\u001b[0m\n\u001b[0;32m    371\u001b[0m \u001b[38;5;28;01mif\u001b[39;00m follow_relative_redirects:\n\u001b[1;32m--> 372\u001b[0m     response \u001b[38;5;241m=\u001b[39m _request_wrapper(\n\u001b[0;32m    373\u001b[0m         method\u001b[38;5;241m=\u001b[39mmethod,\n\u001b[0;32m    374\u001b[0m         url\u001b[38;5;241m=\u001b[39murl,\n\u001b[0;32m    375\u001b[0m         follow_relative_redirects\u001b[38;5;241m=\u001b[39m\u001b[38;5;28;01mFalse\u001b[39;00m,\n\u001b[0;32m    376\u001b[0m         \u001b[38;5;241m*\u001b[39m\u001b[38;5;241m*\u001b[39mparams,\n\u001b[0;32m    377\u001b[0m     )\n\u001b[0;32m    379\u001b[0m     \u001b[38;5;66;03m# If redirection, we redirect only relative paths.\u001b[39;00m\n\u001b[0;32m    380\u001b[0m     \u001b[38;5;66;03m# This is useful in case of a renamed repository.\u001b[39;00m\n",
      "File \u001b[1;32mD:\\Anaconda\\envs\\data_analysis\\lib\\site-packages\\huggingface_hub\\file_download.py:395\u001b[0m, in \u001b[0;36m_request_wrapper\u001b[1;34m(method, url, follow_relative_redirects, **params)\u001b[0m\n\u001b[0;32m    394\u001b[0m \u001b[38;5;66;03m# Perform request and return if status_code is not in the retry list.\u001b[39;00m\n\u001b[1;32m--> 395\u001b[0m response \u001b[38;5;241m=\u001b[39m get_session()\u001b[38;5;241m.\u001b[39mrequest(method\u001b[38;5;241m=\u001b[39mmethod, url\u001b[38;5;241m=\u001b[39murl, \u001b[38;5;241m*\u001b[39m\u001b[38;5;241m*\u001b[39mparams)\n\u001b[0;32m    396\u001b[0m hf_raise_for_status(response)\n",
      "File \u001b[1;32mD:\\Anaconda\\envs\\data_analysis\\lib\\site-packages\\requests\\sessions.py:589\u001b[0m, in \u001b[0;36mSession.request\u001b[1;34m(self, method, url, params, data, headers, cookies, files, auth, timeout, allow_redirects, proxies, hooks, stream, verify, cert, json)\u001b[0m\n\u001b[0;32m    588\u001b[0m send_kwargs\u001b[38;5;241m.\u001b[39mupdate(settings)\n\u001b[1;32m--> 589\u001b[0m resp \u001b[38;5;241m=\u001b[39m \u001b[38;5;28mself\u001b[39m\u001b[38;5;241m.\u001b[39msend(prep, \u001b[38;5;241m*\u001b[39m\u001b[38;5;241m*\u001b[39msend_kwargs)\n\u001b[0;32m    591\u001b[0m \u001b[38;5;28;01mreturn\u001b[39;00m resp\n",
      "File \u001b[1;32mD:\\Anaconda\\envs\\data_analysis\\lib\\site-packages\\requests\\sessions.py:703\u001b[0m, in \u001b[0;36mSession.send\u001b[1;34m(self, request, **kwargs)\u001b[0m\n\u001b[0;32m    702\u001b[0m \u001b[38;5;66;03m# Send the request\u001b[39;00m\n\u001b[1;32m--> 703\u001b[0m r \u001b[38;5;241m=\u001b[39m adapter\u001b[38;5;241m.\u001b[39msend(request, \u001b[38;5;241m*\u001b[39m\u001b[38;5;241m*\u001b[39mkwargs)\n\u001b[0;32m    705\u001b[0m \u001b[38;5;66;03m# Total elapsed time of the request (approximately)\u001b[39;00m\n",
      "File \u001b[1;32mD:\\Anaconda\\envs\\data_analysis\\lib\\site-packages\\huggingface_hub\\utils\\_http.py:66\u001b[0m, in \u001b[0;36mUniqueRequestIdAdapter.send\u001b[1;34m(self, request, *args, **kwargs)\u001b[0m\n\u001b[0;32m     65\u001b[0m \u001b[38;5;28;01mtry\u001b[39;00m:\n\u001b[1;32m---> 66\u001b[0m     \u001b[38;5;28;01mreturn\u001b[39;00m \u001b[38;5;28msuper\u001b[39m()\u001b[38;5;241m.\u001b[39msend(request, \u001b[38;5;241m*\u001b[39margs, \u001b[38;5;241m*\u001b[39m\u001b[38;5;241m*\u001b[39mkwargs)\n\u001b[0;32m     67\u001b[0m \u001b[38;5;28;01mexcept\u001b[39;00m requests\u001b[38;5;241m.\u001b[39mRequestException \u001b[38;5;28;01mas\u001b[39;00m e:\n",
      "File \u001b[1;32mD:\\Anaconda\\envs\\data_analysis\\lib\\site-packages\\requests\\adapters.py:507\u001b[0m, in \u001b[0;36mHTTPAdapter.send\u001b[1;34m(self, request, stream, timeout, verify, cert, proxies)\u001b[0m\n\u001b[0;32m    506\u001b[0m     \u001b[38;5;28;01mif\u001b[39;00m \u001b[38;5;129;01mnot\u001b[39;00m \u001b[38;5;28misinstance\u001b[39m(e\u001b[38;5;241m.\u001b[39mreason, NewConnectionError):\n\u001b[1;32m--> 507\u001b[0m         \u001b[38;5;28;01mraise\u001b[39;00m ConnectTimeout(e, request\u001b[38;5;241m=\u001b[39mrequest)\n\u001b[0;32m    509\u001b[0m \u001b[38;5;28;01mif\u001b[39;00m \u001b[38;5;28misinstance\u001b[39m(e\u001b[38;5;241m.\u001b[39mreason, ResponseError):\n",
      "\u001b[1;31mConnectTimeout\u001b[0m: (MaxRetryError(\"HTTPSConnectionPool(host='huggingface.co', port=443): Max retries exceeded with url: /distilbert/distilbert-base-uncased-finetuned-sst-2-english/resolve/main/config.json (Caused by ConnectTimeoutError(<urllib3.connection.HTTPSConnection object at 0x0000018F28FBF940>, 'Connection to huggingface.co timed out. (connect timeout=10)'))\"), '(Request ID: f716d534-b853-4cab-a3ba-31e64ffe7d5b)')",
      "\nThe above exception was the direct cause of the following exception:\n",
      "\u001b[1;31mLocalEntryNotFoundError\u001b[0m                   Traceback (most recent call last)",
      "File \u001b[1;32mD:\\Anaconda\\envs\\data_analysis\\lib\\site-packages\\transformers\\utils\\hub.py:399\u001b[0m, in \u001b[0;36mcached_file\u001b[1;34m(path_or_repo_id, filename, cache_dir, force_download, resume_download, proxies, token, revision, local_files_only, subfolder, repo_type, user_agent, _raise_exceptions_for_gated_repo, _raise_exceptions_for_missing_entries, _raise_exceptions_for_connection_errors, _commit_hash, **deprecated_kwargs)\u001b[0m\n\u001b[0;32m    397\u001b[0m \u001b[38;5;28;01mtry\u001b[39;00m:\n\u001b[0;32m    398\u001b[0m     \u001b[38;5;66;03m# Load from URL or cache if already cached\u001b[39;00m\n\u001b[1;32m--> 399\u001b[0m     resolved_file \u001b[38;5;241m=\u001b[39m \u001b[43mhf_hub_download\u001b[49m\u001b[43m(\u001b[49m\n\u001b[0;32m    400\u001b[0m \u001b[43m        \u001b[49m\u001b[43mpath_or_repo_id\u001b[49m\u001b[43m,\u001b[49m\n\u001b[0;32m    401\u001b[0m \u001b[43m        \u001b[49m\u001b[43mfilename\u001b[49m\u001b[43m,\u001b[49m\n\u001b[0;32m    402\u001b[0m \u001b[43m        \u001b[49m\u001b[43msubfolder\u001b[49m\u001b[38;5;241;43m=\u001b[39;49m\u001b[38;5;28;43;01mNone\u001b[39;49;00m\u001b[43m \u001b[49m\u001b[38;5;28;43;01mif\u001b[39;49;00m\u001b[43m \u001b[49m\u001b[38;5;28;43mlen\u001b[39;49m\u001b[43m(\u001b[49m\u001b[43msubfolder\u001b[49m\u001b[43m)\u001b[49m\u001b[43m \u001b[49m\u001b[38;5;241;43m==\u001b[39;49m\u001b[43m \u001b[49m\u001b[38;5;241;43m0\u001b[39;49m\u001b[43m \u001b[49m\u001b[38;5;28;43;01melse\u001b[39;49;00m\u001b[43m \u001b[49m\u001b[43msubfolder\u001b[49m\u001b[43m,\u001b[49m\n\u001b[0;32m    403\u001b[0m \u001b[43m        \u001b[49m\u001b[43mrepo_type\u001b[49m\u001b[38;5;241;43m=\u001b[39;49m\u001b[43mrepo_type\u001b[49m\u001b[43m,\u001b[49m\n\u001b[0;32m    404\u001b[0m \u001b[43m        \u001b[49m\u001b[43mrevision\u001b[49m\u001b[38;5;241;43m=\u001b[39;49m\u001b[43mrevision\u001b[49m\u001b[43m,\u001b[49m\n\u001b[0;32m    405\u001b[0m \u001b[43m        \u001b[49m\u001b[43mcache_dir\u001b[49m\u001b[38;5;241;43m=\u001b[39;49m\u001b[43mcache_dir\u001b[49m\u001b[43m,\u001b[49m\n\u001b[0;32m    406\u001b[0m \u001b[43m        \u001b[49m\u001b[43muser_agent\u001b[49m\u001b[38;5;241;43m=\u001b[39;49m\u001b[43muser_agent\u001b[49m\u001b[43m,\u001b[49m\n\u001b[0;32m    407\u001b[0m \u001b[43m        \u001b[49m\u001b[43mforce_download\u001b[49m\u001b[38;5;241;43m=\u001b[39;49m\u001b[43mforce_download\u001b[49m\u001b[43m,\u001b[49m\n\u001b[0;32m    408\u001b[0m \u001b[43m        \u001b[49m\u001b[43mproxies\u001b[49m\u001b[38;5;241;43m=\u001b[39;49m\u001b[43mproxies\u001b[49m\u001b[43m,\u001b[49m\n\u001b[0;32m    409\u001b[0m \u001b[43m        \u001b[49m\u001b[43mresume_download\u001b[49m\u001b[38;5;241;43m=\u001b[39;49m\u001b[43mresume_download\u001b[49m\u001b[43m,\u001b[49m\n\u001b[0;32m    410\u001b[0m \u001b[43m        \u001b[49m\u001b[43mtoken\u001b[49m\u001b[38;5;241;43m=\u001b[39;49m\u001b[43mtoken\u001b[49m\u001b[43m,\u001b[49m\n\u001b[0;32m    411\u001b[0m \u001b[43m        \u001b[49m\u001b[43mlocal_files_only\u001b[49m\u001b[38;5;241;43m=\u001b[39;49m\u001b[43mlocal_files_only\u001b[49m\u001b[43m,\u001b[49m\n\u001b[0;32m    412\u001b[0m \u001b[43m    \u001b[49m\u001b[43m)\u001b[49m\n\u001b[0;32m    413\u001b[0m \u001b[38;5;28;01mexcept\u001b[39;00m GatedRepoError \u001b[38;5;28;01mas\u001b[39;00m e:\n",
      "File \u001b[1;32mD:\\Anaconda\\envs\\data_analysis\\lib\\site-packages\\huggingface_hub\\utils\\_validators.py:114\u001b[0m, in \u001b[0;36mvalidate_hf_hub_args.<locals>._inner_fn\u001b[1;34m(*args, **kwargs)\u001b[0m\n\u001b[0;32m    112\u001b[0m     kwargs \u001b[38;5;241m=\u001b[39m smoothly_deprecate_use_auth_token(fn_name\u001b[38;5;241m=\u001b[39mfn\u001b[38;5;241m.\u001b[39m\u001b[38;5;18m__name__\u001b[39m, has_token\u001b[38;5;241m=\u001b[39mhas_token, kwargs\u001b[38;5;241m=\u001b[39mkwargs)\n\u001b[1;32m--> 114\u001b[0m \u001b[38;5;28;01mreturn\u001b[39;00m fn(\u001b[38;5;241m*\u001b[39margs, \u001b[38;5;241m*\u001b[39m\u001b[38;5;241m*\u001b[39mkwargs)\n",
      "File \u001b[1;32mD:\\Anaconda\\envs\\data_analysis\\lib\\site-packages\\huggingface_hub\\file_download.py:1221\u001b[0m, in \u001b[0;36mhf_hub_download\u001b[1;34m(repo_id, filename, subfolder, repo_type, revision, library_name, library_version, cache_dir, local_dir, user_agent, force_download, proxies, etag_timeout, token, local_files_only, headers, endpoint, legacy_cache_layout, resume_download, force_filename, local_dir_use_symlinks)\u001b[0m\n\u001b[0;32m   1220\u001b[0m \u001b[38;5;28;01melse\u001b[39;00m:\n\u001b[1;32m-> 1221\u001b[0m     \u001b[38;5;28;01mreturn\u001b[39;00m \u001b[43m_hf_hub_download_to_cache_dir\u001b[49m\u001b[43m(\u001b[49m\n\u001b[0;32m   1222\u001b[0m \u001b[43m        \u001b[49m\u001b[38;5;66;43;03m# Destination\u001b[39;49;00m\n\u001b[0;32m   1223\u001b[0m \u001b[43m        \u001b[49m\u001b[43mcache_dir\u001b[49m\u001b[38;5;241;43m=\u001b[39;49m\u001b[43mcache_dir\u001b[49m\u001b[43m,\u001b[49m\n\u001b[0;32m   1224\u001b[0m \u001b[43m        \u001b[49m\u001b[38;5;66;43;03m# File info\u001b[39;49;00m\n\u001b[0;32m   1225\u001b[0m \u001b[43m        \u001b[49m\u001b[43mrepo_id\u001b[49m\u001b[38;5;241;43m=\u001b[39;49m\u001b[43mrepo_id\u001b[49m\u001b[43m,\u001b[49m\n\u001b[0;32m   1226\u001b[0m \u001b[43m        \u001b[49m\u001b[43mfilename\u001b[49m\u001b[38;5;241;43m=\u001b[39;49m\u001b[43mfilename\u001b[49m\u001b[43m,\u001b[49m\n\u001b[0;32m   1227\u001b[0m \u001b[43m        \u001b[49m\u001b[43mrepo_type\u001b[49m\u001b[38;5;241;43m=\u001b[39;49m\u001b[43mrepo_type\u001b[49m\u001b[43m,\u001b[49m\n\u001b[0;32m   1228\u001b[0m \u001b[43m        \u001b[49m\u001b[43mrevision\u001b[49m\u001b[38;5;241;43m=\u001b[39;49m\u001b[43mrevision\u001b[49m\u001b[43m,\u001b[49m\n\u001b[0;32m   1229\u001b[0m \u001b[43m        \u001b[49m\u001b[38;5;66;43;03m# HTTP info\u001b[39;49;00m\n\u001b[0;32m   1230\u001b[0m \u001b[43m        \u001b[49m\u001b[43mheaders\u001b[49m\u001b[38;5;241;43m=\u001b[39;49m\u001b[43mheaders\u001b[49m\u001b[43m,\u001b[49m\n\u001b[0;32m   1231\u001b[0m \u001b[43m        \u001b[49m\u001b[43mproxies\u001b[49m\u001b[38;5;241;43m=\u001b[39;49m\u001b[43mproxies\u001b[49m\u001b[43m,\u001b[49m\n\u001b[0;32m   1232\u001b[0m \u001b[43m        \u001b[49m\u001b[43metag_timeout\u001b[49m\u001b[38;5;241;43m=\u001b[39;49m\u001b[43metag_timeout\u001b[49m\u001b[43m,\u001b[49m\n\u001b[0;32m   1233\u001b[0m \u001b[43m        \u001b[49m\u001b[43mendpoint\u001b[49m\u001b[38;5;241;43m=\u001b[39;49m\u001b[43mendpoint\u001b[49m\u001b[43m,\u001b[49m\n\u001b[0;32m   1234\u001b[0m \u001b[43m        \u001b[49m\u001b[38;5;66;43;03m# Additional options\u001b[39;49;00m\n\u001b[0;32m   1235\u001b[0m \u001b[43m        \u001b[49m\u001b[43mlocal_files_only\u001b[49m\u001b[38;5;241;43m=\u001b[39;49m\u001b[43mlocal_files_only\u001b[49m\u001b[43m,\u001b[49m\n\u001b[0;32m   1236\u001b[0m \u001b[43m        \u001b[49m\u001b[43mforce_download\u001b[49m\u001b[38;5;241;43m=\u001b[39;49m\u001b[43mforce_download\u001b[49m\u001b[43m,\u001b[49m\n\u001b[0;32m   1237\u001b[0m \u001b[43m    \u001b[49m\u001b[43m)\u001b[49m\n",
      "File \u001b[1;32mD:\\Anaconda\\envs\\data_analysis\\lib\\site-packages\\huggingface_hub\\file_download.py:1325\u001b[0m, in \u001b[0;36m_hf_hub_download_to_cache_dir\u001b[1;34m(cache_dir, repo_id, filename, repo_type, revision, headers, proxies, etag_timeout, endpoint, local_files_only, force_download)\u001b[0m\n\u001b[0;32m   1324\u001b[0m     \u001b[38;5;66;03m# Otherwise, raise appropriate error\u001b[39;00m\n\u001b[1;32m-> 1325\u001b[0m     \u001b[43m_raise_on_head_call_error\u001b[49m\u001b[43m(\u001b[49m\u001b[43mhead_call_error\u001b[49m\u001b[43m,\u001b[49m\u001b[43m \u001b[49m\u001b[43mforce_download\u001b[49m\u001b[43m,\u001b[49m\u001b[43m \u001b[49m\u001b[43mlocal_files_only\u001b[49m\u001b[43m)\u001b[49m\n\u001b[0;32m   1327\u001b[0m \u001b[38;5;66;03m# From now on, etag, commit_hash, url and size are not None.\u001b[39;00m\n",
      "File \u001b[1;32mD:\\Anaconda\\envs\\data_analysis\\lib\\site-packages\\huggingface_hub\\file_download.py:1826\u001b[0m, in \u001b[0;36m_raise_on_head_call_error\u001b[1;34m(head_call_error, force_download, local_files_only)\u001b[0m\n\u001b[0;32m   1824\u001b[0m \u001b[38;5;28;01melse\u001b[39;00m:\n\u001b[0;32m   1825\u001b[0m     \u001b[38;5;66;03m# Otherwise: most likely a connection issue or Hub downtime => let's warn the user\u001b[39;00m\n\u001b[1;32m-> 1826\u001b[0m     \u001b[38;5;28;01mraise\u001b[39;00m LocalEntryNotFoundError(\n\u001b[0;32m   1827\u001b[0m         \u001b[38;5;124m\"\u001b[39m\u001b[38;5;124mAn error happened while trying to locate the file on the Hub and we cannot find the requested files\u001b[39m\u001b[38;5;124m\"\u001b[39m\n\u001b[0;32m   1828\u001b[0m         \u001b[38;5;124m\"\u001b[39m\u001b[38;5;124m in the local cache. Please check your connection and try again or make sure your Internet connection\u001b[39m\u001b[38;5;124m\"\u001b[39m\n\u001b[0;32m   1829\u001b[0m         \u001b[38;5;124m\"\u001b[39m\u001b[38;5;124m is on.\u001b[39m\u001b[38;5;124m\"\u001b[39m\n\u001b[0;32m   1830\u001b[0m     ) \u001b[38;5;28;01mfrom\u001b[39;00m \u001b[38;5;21;01mhead_call_error\u001b[39;00m\n",
      "\u001b[1;31mLocalEntryNotFoundError\u001b[0m: An error happened while trying to locate the file on the Hub and we cannot find the requested files in the local cache. Please check your connection and try again or make sure your Internet connection is on.",
      "\nThe above exception was the direct cause of the following exception:\n",
      "\u001b[1;31mOSError\u001b[0m                                   Traceback (most recent call last)",
      "Cell \u001b[1;32mIn[12], line 3\u001b[0m\n\u001b[0;32m      1\u001b[0m \u001b[38;5;28;01mfrom\u001b[39;00m \u001b[38;5;21;01mtransformers\u001b[39;00m \u001b[38;5;28;01mimport\u001b[39;00m pipeline\n\u001b[1;32m----> 3\u001b[0m classifier \u001b[38;5;241m=\u001b[39m \u001b[43mpipeline\u001b[49m\u001b[43m(\u001b[49m\u001b[38;5;124;43m\"\u001b[39;49m\u001b[38;5;124;43msentiment-analysis\u001b[39;49m\u001b[38;5;124;43m\"\u001b[39;49m\u001b[43m)\u001b[49m\n\u001b[0;32m      4\u001b[0m classifier(\u001b[38;5;124m\"\u001b[39m\u001b[38;5;124mI\u001b[39m\u001b[38;5;124m'\u001b[39m\u001b[38;5;124mve been waiting for a HuggingFace course my whole life.\u001b[39m\u001b[38;5;124m\"\u001b[39m)\n",
      "File \u001b[1;32mD:\\Anaconda\\envs\\data_analysis\\lib\\site-packages\\transformers\\pipelines\\__init__.py:875\u001b[0m, in \u001b[0;36mpipeline\u001b[1;34m(task, model, config, tokenizer, feature_extractor, image_processor, framework, revision, use_fast, token, device, device_map, torch_dtype, trust_remote_code, model_kwargs, pipeline_class, **kwargs)\u001b[0m\n\u001b[0;32m    869\u001b[0m     logger\u001b[38;5;241m.\u001b[39mwarning(\n\u001b[0;32m    870\u001b[0m         \u001b[38;5;124mf\u001b[39m\u001b[38;5;124m\"\u001b[39m\u001b[38;5;124mNo model was supplied, defaulted to \u001b[39m\u001b[38;5;132;01m{\u001b[39;00mmodel\u001b[38;5;132;01m}\u001b[39;00m\u001b[38;5;124m and revision\u001b[39m\u001b[38;5;124m\"\u001b[39m\n\u001b[0;32m    871\u001b[0m         \u001b[38;5;124mf\u001b[39m\u001b[38;5;124m\"\u001b[39m\u001b[38;5;124m \u001b[39m\u001b[38;5;132;01m{\u001b[39;00mrevision\u001b[38;5;132;01m}\u001b[39;00m\u001b[38;5;124m (\u001b[39m\u001b[38;5;132;01m{\u001b[39;00mHUGGINGFACE_CO_RESOLVE_ENDPOINT\u001b[38;5;132;01m}\u001b[39;00m\u001b[38;5;124m/\u001b[39m\u001b[38;5;132;01m{\u001b[39;00mmodel\u001b[38;5;132;01m}\u001b[39;00m\u001b[38;5;124m).\u001b[39m\u001b[38;5;130;01m\\n\u001b[39;00m\u001b[38;5;124m\"\u001b[39m\n\u001b[0;32m    872\u001b[0m         \u001b[38;5;124m\"\u001b[39m\u001b[38;5;124mUsing a pipeline without specifying a model name and revision in production is not recommended.\u001b[39m\u001b[38;5;124m\"\u001b[39m\n\u001b[0;32m    873\u001b[0m     )\n\u001b[0;32m    874\u001b[0m     \u001b[38;5;28;01mif\u001b[39;00m config \u001b[38;5;129;01mis\u001b[39;00m \u001b[38;5;28;01mNone\u001b[39;00m \u001b[38;5;129;01mand\u001b[39;00m \u001b[38;5;28misinstance\u001b[39m(model, \u001b[38;5;28mstr\u001b[39m):\n\u001b[1;32m--> 875\u001b[0m         config \u001b[38;5;241m=\u001b[39m AutoConfig\u001b[38;5;241m.\u001b[39mfrom_pretrained(model, _from_pipeline\u001b[38;5;241m=\u001b[39mtask, \u001b[38;5;241m*\u001b[39m\u001b[38;5;241m*\u001b[39mhub_kwargs, \u001b[38;5;241m*\u001b[39m\u001b[38;5;241m*\u001b[39mmodel_kwargs)\n\u001b[0;32m    876\u001b[0m         hub_kwargs[\u001b[38;5;124m\"\u001b[39m\u001b[38;5;124m_commit_hash\u001b[39m\u001b[38;5;124m\"\u001b[39m] \u001b[38;5;241m=\u001b[39m config\u001b[38;5;241m.\u001b[39m_commit_hash\n\u001b[0;32m    878\u001b[0m \u001b[38;5;28;01mif\u001b[39;00m device_map \u001b[38;5;129;01mis\u001b[39;00m \u001b[38;5;129;01mnot\u001b[39;00m \u001b[38;5;28;01mNone\u001b[39;00m:\n",
      "File \u001b[1;32mD:\\Anaconda\\envs\\data_analysis\\lib\\site-packages\\transformers\\models\\auto\\configuration_auto.py:934\u001b[0m, in \u001b[0;36mAutoConfig.from_pretrained\u001b[1;34m(cls, pretrained_model_name_or_path, **kwargs)\u001b[0m\n\u001b[0;32m    931\u001b[0m trust_remote_code \u001b[38;5;241m=\u001b[39m kwargs\u001b[38;5;241m.\u001b[39mpop(\u001b[38;5;124m\"\u001b[39m\u001b[38;5;124mtrust_remote_code\u001b[39m\u001b[38;5;124m\"\u001b[39m, \u001b[38;5;28;01mNone\u001b[39;00m)\n\u001b[0;32m    932\u001b[0m code_revision \u001b[38;5;241m=\u001b[39m kwargs\u001b[38;5;241m.\u001b[39mpop(\u001b[38;5;124m\"\u001b[39m\u001b[38;5;124mcode_revision\u001b[39m\u001b[38;5;124m\"\u001b[39m, \u001b[38;5;28;01mNone\u001b[39;00m)\n\u001b[1;32m--> 934\u001b[0m config_dict, unused_kwargs \u001b[38;5;241m=\u001b[39m PretrainedConfig\u001b[38;5;241m.\u001b[39mget_config_dict(pretrained_model_name_or_path, \u001b[38;5;241m*\u001b[39m\u001b[38;5;241m*\u001b[39mkwargs)\n\u001b[0;32m    935\u001b[0m has_remote_code \u001b[38;5;241m=\u001b[39m \u001b[38;5;124m\"\u001b[39m\u001b[38;5;124mauto_map\u001b[39m\u001b[38;5;124m\"\u001b[39m \u001b[38;5;129;01min\u001b[39;00m config_dict \u001b[38;5;129;01mand\u001b[39;00m \u001b[38;5;124m\"\u001b[39m\u001b[38;5;124mAutoConfig\u001b[39m\u001b[38;5;124m\"\u001b[39m \u001b[38;5;129;01min\u001b[39;00m config_dict[\u001b[38;5;124m\"\u001b[39m\u001b[38;5;124mauto_map\u001b[39m\u001b[38;5;124m\"\u001b[39m]\n\u001b[0;32m    936\u001b[0m has_local_code \u001b[38;5;241m=\u001b[39m \u001b[38;5;124m\"\u001b[39m\u001b[38;5;124mmodel_type\u001b[39m\u001b[38;5;124m\"\u001b[39m \u001b[38;5;129;01min\u001b[39;00m config_dict \u001b[38;5;129;01mand\u001b[39;00m config_dict[\u001b[38;5;124m\"\u001b[39m\u001b[38;5;124mmodel_type\u001b[39m\u001b[38;5;124m\"\u001b[39m] \u001b[38;5;129;01min\u001b[39;00m CONFIG_MAPPING\n",
      "File \u001b[1;32mD:\\Anaconda\\envs\\data_analysis\\lib\\site-packages\\transformers\\configuration_utils.py:632\u001b[0m, in \u001b[0;36mPretrainedConfig.get_config_dict\u001b[1;34m(cls, pretrained_model_name_or_path, **kwargs)\u001b[0m\n\u001b[0;32m    630\u001b[0m original_kwargs \u001b[38;5;241m=\u001b[39m copy\u001b[38;5;241m.\u001b[39mdeepcopy(kwargs)\n\u001b[0;32m    631\u001b[0m \u001b[38;5;66;03m# Get config dict associated with the base config file\u001b[39;00m\n\u001b[1;32m--> 632\u001b[0m config_dict, kwargs \u001b[38;5;241m=\u001b[39m \u001b[38;5;28mcls\u001b[39m\u001b[38;5;241m.\u001b[39m_get_config_dict(pretrained_model_name_or_path, \u001b[38;5;241m*\u001b[39m\u001b[38;5;241m*\u001b[39mkwargs)\n\u001b[0;32m    633\u001b[0m \u001b[38;5;28;01mif\u001b[39;00m \u001b[38;5;124m\"\u001b[39m\u001b[38;5;124m_commit_hash\u001b[39m\u001b[38;5;124m\"\u001b[39m \u001b[38;5;129;01min\u001b[39;00m config_dict:\n\u001b[0;32m    634\u001b[0m     original_kwargs[\u001b[38;5;124m\"\u001b[39m\u001b[38;5;124m_commit_hash\u001b[39m\u001b[38;5;124m\"\u001b[39m] \u001b[38;5;241m=\u001b[39m config_dict[\u001b[38;5;124m\"\u001b[39m\u001b[38;5;124m_commit_hash\u001b[39m\u001b[38;5;124m\"\u001b[39m]\n",
      "File \u001b[1;32mD:\\Anaconda\\envs\\data_analysis\\lib\\site-packages\\transformers\\configuration_utils.py:689\u001b[0m, in \u001b[0;36mPretrainedConfig._get_config_dict\u001b[1;34m(cls, pretrained_model_name_or_path, **kwargs)\u001b[0m\n\u001b[0;32m    685\u001b[0m configuration_file \u001b[38;5;241m=\u001b[39m kwargs\u001b[38;5;241m.\u001b[39mpop(\u001b[38;5;124m\"\u001b[39m\u001b[38;5;124m_configuration_file\u001b[39m\u001b[38;5;124m\"\u001b[39m, CONFIG_NAME) \u001b[38;5;28;01mif\u001b[39;00m gguf_file \u001b[38;5;129;01mis\u001b[39;00m \u001b[38;5;28;01mNone\u001b[39;00m \u001b[38;5;28;01melse\u001b[39;00m gguf_file\n\u001b[0;32m    687\u001b[0m \u001b[38;5;28;01mtry\u001b[39;00m:\n\u001b[0;32m    688\u001b[0m     \u001b[38;5;66;03m# Load from local folder or from cache or download from model Hub and cache\u001b[39;00m\n\u001b[1;32m--> 689\u001b[0m     resolved_config_file \u001b[38;5;241m=\u001b[39m \u001b[43mcached_file\u001b[49m\u001b[43m(\u001b[49m\n\u001b[0;32m    690\u001b[0m \u001b[43m        \u001b[49m\u001b[43mpretrained_model_name_or_path\u001b[49m\u001b[43m,\u001b[49m\n\u001b[0;32m    691\u001b[0m \u001b[43m        \u001b[49m\u001b[43mconfiguration_file\u001b[49m\u001b[43m,\u001b[49m\n\u001b[0;32m    692\u001b[0m \u001b[43m        \u001b[49m\u001b[43mcache_dir\u001b[49m\u001b[38;5;241;43m=\u001b[39;49m\u001b[43mcache_dir\u001b[49m\u001b[43m,\u001b[49m\n\u001b[0;32m    693\u001b[0m \u001b[43m        \u001b[49m\u001b[43mforce_download\u001b[49m\u001b[38;5;241;43m=\u001b[39;49m\u001b[43mforce_download\u001b[49m\u001b[43m,\u001b[49m\n\u001b[0;32m    694\u001b[0m \u001b[43m        \u001b[49m\u001b[43mproxies\u001b[49m\u001b[38;5;241;43m=\u001b[39;49m\u001b[43mproxies\u001b[49m\u001b[43m,\u001b[49m\n\u001b[0;32m    695\u001b[0m \u001b[43m        \u001b[49m\u001b[43mresume_download\u001b[49m\u001b[38;5;241;43m=\u001b[39;49m\u001b[43mresume_download\u001b[49m\u001b[43m,\u001b[49m\n\u001b[0;32m    696\u001b[0m \u001b[43m        \u001b[49m\u001b[43mlocal_files_only\u001b[49m\u001b[38;5;241;43m=\u001b[39;49m\u001b[43mlocal_files_only\u001b[49m\u001b[43m,\u001b[49m\n\u001b[0;32m    697\u001b[0m \u001b[43m        \u001b[49m\u001b[43mtoken\u001b[49m\u001b[38;5;241;43m=\u001b[39;49m\u001b[43mtoken\u001b[49m\u001b[43m,\u001b[49m\n\u001b[0;32m    698\u001b[0m \u001b[43m        \u001b[49m\u001b[43muser_agent\u001b[49m\u001b[38;5;241;43m=\u001b[39;49m\u001b[43muser_agent\u001b[49m\u001b[43m,\u001b[49m\n\u001b[0;32m    699\u001b[0m \u001b[43m        \u001b[49m\u001b[43mrevision\u001b[49m\u001b[38;5;241;43m=\u001b[39;49m\u001b[43mrevision\u001b[49m\u001b[43m,\u001b[49m\n\u001b[0;32m    700\u001b[0m \u001b[43m        \u001b[49m\u001b[43msubfolder\u001b[49m\u001b[38;5;241;43m=\u001b[39;49m\u001b[43msubfolder\u001b[49m\u001b[43m,\u001b[49m\n\u001b[0;32m    701\u001b[0m \u001b[43m        \u001b[49m\u001b[43m_commit_hash\u001b[49m\u001b[38;5;241;43m=\u001b[39;49m\u001b[43mcommit_hash\u001b[49m\u001b[43m,\u001b[49m\n\u001b[0;32m    702\u001b[0m \u001b[43m    \u001b[49m\u001b[43m)\u001b[49m\n\u001b[0;32m    703\u001b[0m     commit_hash \u001b[38;5;241m=\u001b[39m extract_commit_hash(resolved_config_file, commit_hash)\n\u001b[0;32m    704\u001b[0m \u001b[38;5;28;01mexcept\u001b[39;00m \u001b[38;5;167;01mEnvironmentError\u001b[39;00m:\n\u001b[0;32m    705\u001b[0m     \u001b[38;5;66;03m# Raise any environment error raise by `cached_file`. It will have a helpful error message adapted to\u001b[39;00m\n\u001b[0;32m    706\u001b[0m     \u001b[38;5;66;03m# the original exception.\u001b[39;00m\n",
      "File \u001b[1;32mD:\\Anaconda\\envs\\data_analysis\\lib\\site-packages\\transformers\\utils\\hub.py:442\u001b[0m, in \u001b[0;36mcached_file\u001b[1;34m(path_or_repo_id, filename, cache_dir, force_download, resume_download, proxies, token, revision, local_files_only, subfolder, repo_type, user_agent, _raise_exceptions_for_gated_repo, _raise_exceptions_for_missing_entries, _raise_exceptions_for_connection_errors, _commit_hash, **deprecated_kwargs)\u001b[0m\n\u001b[0;32m    436\u001b[0m     \u001b[38;5;28;01mif\u001b[39;00m (\n\u001b[0;32m    437\u001b[0m         resolved_file \u001b[38;5;129;01mis\u001b[39;00m \u001b[38;5;129;01mnot\u001b[39;00m \u001b[38;5;28;01mNone\u001b[39;00m\n\u001b[0;32m    438\u001b[0m         \u001b[38;5;129;01mor\u001b[39;00m \u001b[38;5;129;01mnot\u001b[39;00m _raise_exceptions_for_missing_entries\n\u001b[0;32m    439\u001b[0m         \u001b[38;5;129;01mor\u001b[39;00m \u001b[38;5;129;01mnot\u001b[39;00m _raise_exceptions_for_connection_errors\n\u001b[0;32m    440\u001b[0m     ):\n\u001b[0;32m    441\u001b[0m         \u001b[38;5;28;01mreturn\u001b[39;00m resolved_file\n\u001b[1;32m--> 442\u001b[0m     \u001b[38;5;28;01mraise\u001b[39;00m \u001b[38;5;167;01mEnvironmentError\u001b[39;00m(\n\u001b[0;32m    443\u001b[0m         \u001b[38;5;124mf\u001b[39m\u001b[38;5;124m\"\u001b[39m\u001b[38;5;124mWe couldn\u001b[39m\u001b[38;5;124m'\u001b[39m\u001b[38;5;124mt connect to \u001b[39m\u001b[38;5;124m'\u001b[39m\u001b[38;5;132;01m{\u001b[39;00mHUGGINGFACE_CO_RESOLVE_ENDPOINT\u001b[38;5;132;01m}\u001b[39;00m\u001b[38;5;124m'\u001b[39m\u001b[38;5;124m to load this file, couldn\u001b[39m\u001b[38;5;124m'\u001b[39m\u001b[38;5;124mt find it in the\u001b[39m\u001b[38;5;124m\"\u001b[39m\n\u001b[0;32m    444\u001b[0m         \u001b[38;5;124mf\u001b[39m\u001b[38;5;124m\"\u001b[39m\u001b[38;5;124m cached files and it looks like \u001b[39m\u001b[38;5;132;01m{\u001b[39;00mpath_or_repo_id\u001b[38;5;132;01m}\u001b[39;00m\u001b[38;5;124m is not the path to a directory containing a file named\u001b[39m\u001b[38;5;124m\"\u001b[39m\n\u001b[0;32m    445\u001b[0m         \u001b[38;5;124mf\u001b[39m\u001b[38;5;124m\"\u001b[39m\u001b[38;5;124m \u001b[39m\u001b[38;5;132;01m{\u001b[39;00mfull_filename\u001b[38;5;132;01m}\u001b[39;00m\u001b[38;5;124m.\u001b[39m\u001b[38;5;130;01m\\n\u001b[39;00m\u001b[38;5;124mCheckout your internet connection or see how to run the library in offline mode at\u001b[39m\u001b[38;5;124m\"\u001b[39m\n\u001b[0;32m    446\u001b[0m         \u001b[38;5;124m\"\u001b[39m\u001b[38;5;124m \u001b[39m\u001b[38;5;124m'\u001b[39m\u001b[38;5;124mhttps://huggingface.co/docs/transformers/installation#offline-mode\u001b[39m\u001b[38;5;124m'\u001b[39m\u001b[38;5;124m.\u001b[39m\u001b[38;5;124m\"\u001b[39m\n\u001b[0;32m    447\u001b[0m     ) \u001b[38;5;28;01mfrom\u001b[39;00m \u001b[38;5;21;01me\u001b[39;00m\n\u001b[0;32m    448\u001b[0m \u001b[38;5;28;01mexcept\u001b[39;00m EntryNotFoundError \u001b[38;5;28;01mas\u001b[39;00m e:\n\u001b[0;32m    449\u001b[0m     \u001b[38;5;28;01mif\u001b[39;00m \u001b[38;5;129;01mnot\u001b[39;00m _raise_exceptions_for_missing_entries:\n",
      "\u001b[1;31mOSError\u001b[0m: We couldn't connect to 'https://huggingface.co' to load this file, couldn't find it in the cached files and it looks like distilbert/distilbert-base-uncased-finetuned-sst-2-english is not the path to a directory containing a file named config.json.\nCheckout your internet connection or see how to run the library in offline mode at 'https://huggingface.co/docs/transformers/installation#offline-mode'."
     ]
    }
   ],
   "source": [
    "from transformers import pipeline\n",
    "\n",
    "classifier = pipeline(\"sentiment-analysis\")\n",
    "classifier(\"I've been waiting for a HuggingFace course my whole life.\")"
   ]
  },
  {
   "cell_type": "code",
   "execution_count": null,
   "id": "a7181711-3156-4037-b673-c843c3425c4f",
   "metadata": {},
   "outputs": [],
   "source": []
  },
  {
   "cell_type": "code",
   "execution_count": null,
   "id": "4494da1e-3df0-405a-99ae-a6ce74c71654",
   "metadata": {},
   "outputs": [],
   "source": []
  },
  {
   "cell_type": "code",
   "execution_count": null,
   "id": "7b9fb677-355e-4b77-adcb-c78738bb5463",
   "metadata": {},
   "outputs": [],
   "source": []
  }
 ],
 "metadata": {
  "kernelspec": {
   "display_name": "Python 3 (ipykernel)",
   "language": "python",
   "name": "python3"
  },
  "language_info": {
   "codemirror_mode": {
    "name": "ipython",
    "version": 3
   },
   "file_extension": ".py",
   "mimetype": "text/x-python",
   "name": "python",
   "nbconvert_exporter": "python",
   "pygments_lexer": "ipython3",
   "version": "3.9.0"
  }
 },
 "nbformat": 4,
 "nbformat_minor": 5
}
